Workbook
Name An_Ex: Sheet1!$G$9
Name IL_mang: Sheet1!$G$14
Name suc_fee: Sheet1!$G$15
Name TS_Eq: Sheet1!$G$8
Name TS_Share: Sheet1!$G$6

Sheet Project Budget and Assumptions
A1: Project Budget | E1: Project Assumptions
A3: Land Costs | E3: Parameters used in Calculations
A4: Property purchase | C4: 14000000 | E4: Category/Scenario | F4: Amount | G4: Note
A5: Total Property Costs | C5: =SUM(C4:C4) -> 14000000 | E5: Inflation | F5: 0.02 | G5: Based on the country inflation
E6: Ancilary Revenue | F6: 0.04 | G6: of Rooms Revenue (airport transfers, additional services commision on breakfast operator)
A7: Construction Costs | E7: Cost of Ancilary Revenues | F7: 0.3 | G7: of ancilary revenue
A8: Unit improvements | B8: 12,000 per Unit | C8: =118*12000 -> 1416000 | E8: Management Fee | F8: 0.12 | G8: of total revenue
A9: additional Units construction | B9: 55,000 per Unit | C9: =8*55000 -> 440000 | E9: Reserved for Replacement % | F9: 0.025 | G9: of Rooms Revenue
A10: Facade renovation | C10: 130000 | E10: Miscellaneous expenses % | F10: 0.015 | G10: of Rooms Revenue (including HK Products)
A11: interior renovation | C11: 370000 | E11: Loan-to-Value (LTV) Ratio of Bank Loan | F11: 0.5 | G11: of total project cost
A12: Contingency | B12: 5% of costs | C12: 114000 | E12: Exit Cap Rate | F12: 0.055 | G12: Based on Industry Standards (HVS)
A13: Total Construction Costs | C13: =SUM(C8:C12) -> 2470000 | E13: Discount Factor | F13: 0.08 | G13: Industry average return for city hotels
E14: Annual Interes rate | F14: 0.02
A15: Closing Costs | E15: Utilities cost | F15: 0.065 | G15: of total Revenue. Industry Standard
A16: Broker Fee | B16: 0.0135 | C16: =B16*C4 -> 189000 | E16: F&B Revenues | G16: of rooms revenue. Based on industry standard
A17: Legal Costs/ Due Diligence | B17: 0.005 | C17: =B17*C4 -> 70000 | E17: Cost of F&B Revenues | G17: Based on Industry Standards (HVS)
A18: Planning | C18: 60000 | E18: Operator's Share of NOI | F18: 0.225
A19: Municipal Costs (permits) | C19: 40000 | E19: Investor's GP Asset Management Fee | F19: 0.015
A20: Transaction Fee | B20: 0.02 | C20: =B20*(C4+C13) -> 329400 | E20: Investor's GP Promote | F20: 0.2 | G20: Over 7% Preffered with Full Catch Up
A21: Total Closing Costs | C21: =SUM(C16:C20) -> 688400
A22: Reserve | C22: 350000
A24: Project Budget | C24: =C5+C13+C21+C22 -> 17508400
F28: 1

Sheet Sheet1
B2: Investment Summary | J2: Initiation Cost - IL
B3: Total Project Value (Equity & Finance) | G3: ='Project Budget and Assumptions'!C24 -> 17508400 | J3: Legal | L3: 6000
B4: Total Equity For The Project | G4: ='Fin Calc'!C7 -> 8754200 | J4: Broker | L4: =G4*0.01 -> 87542
B5: TS Equity Invested In The Project | G5: ='Fin Calc'!C7*TS_Share -> 7878780 | J5: D.D | L5: 5000
B6: TS Share Of The Project | G6: 0.9 | J6: Bank Acount | L6: 3000
B7: Initiation Expenses (Inc. VAT) | D7: =G7/(G3*G6) -> 0.025535001 | G7: =L11 -> 402369.32 | J7: Esscrow
B8: Total Equity Raised By TS Investors | G8: =G5+G7 -> 8281149.3 | J8: Tax Memo | L8: 6000
B9: Annual Expenses (Inc. VAT) | G9: =25000*1.17 -> 29250 | J9: Est. expenses | K9: 0.005 | L9: =G3*TS_Share*K9 -> 78787.8
B10: Prefered Ongoing Distribution | G10: 0.07 | J10: Under wrighting | K10: 0.01 | L10: =G3*G6*K10 -> 157575.6
B11: Split Above Preferred | G11: 0.8 | J11: Total | L11: =SUM(L3:L10)*1.17 -> 402369.32
B12: Exit Cap assumption | G12: ='Project Budget and Assumptions'!F12 -> 0.055
B13: Investment Period (years) | G13: 6
B14: IL GP Mnagement Fee | G14: 0.005
B15: IL GP success fee | G15: 0.15
B17: Free Cash Flow
B18: Year | D18: Investment | E18: ='Investor Returns'!E8 -> Construction | F18: ='Investor Returns'!F8 -> Op Year 1 | G18: ='Investor Returns'!G8 -> Op Year 2 | H18: ='Investor Returns'!H8 -> Op Year 3 | I18: ='Investor Returns'!I8 -> Op Year 4 | J18: ='Investor Returns'!J8 -> Op Year 5
B19: Equity | D19: =-TS_Eq -> -8281149.3 | E19: =-TS_Eq -> -8281149.3 | F19: =-TS_Eq -> -8281149.3 | G19: =-TS_Eq -> -8281149.3 | H19: =-TS_Eq -> -8281149.3 | I19: =-TS_Eq -> -8281149.3 | J19: =-TS_Eq -> -8281149.3
B20: Equity Repatriation / Sales Proceeds | F20: 0 | G20: 0 | H20: 0 | J20: =D38 -> 15843619
B21: Ongoing CF | F21: ='Annual Projections (Full)'!D45 -> 1010501.5 | G21: ='Annual Projections (Full)'!E45 -> 1056404.5 | H21: ='Annual Projections (Full)'!F45 -> 1103684.7 | I21: ='Annual Projections (Full)'!G45 -> 1152383.2 | J21: ='Annual Projections (Full)'!H45 -> 1202542.7
B22: Management Fee | E22: =-TS_Eq*IL_mang -> -41405.747 | F22: =-TS_Eq*IL_mang -> -41405.747 | G22: =-TS_Eq*IL_mang -> -41405.747 | H22: =-TS_Eq*IL_mang -> -41405.747 | I22: =-TS_Eq*IL_mang -> -41405.747 | J22: =-TS_Eq*IL_mang -> -41405.747
B23: Annual Expenses | D23: 0 | E23: =-An_Ex -> -29250 | F23: =-An_Ex -> -29250 | G23: =-An_Ex -> -29250 | H23: =-An_Ex -> -29250 | I23: =-An_Ex -> -29250 | J23: =-An_Ex -> -29250
B24: Total CF | D24: =D19 -> -8281149.3 | E24: 0 | F24: =SUM(F20:F23) -> 939845.74 | G24: =SUM(G20:G23) -> 985748.78 | H24: =SUM(H20:H23) -> 1033028.9 | I24: =SUM(I20:I23) -> 1081727.4 | J24: =SUM(J20:J23) -> 16975506
B25: COC | E25: =-SUM(E21:E23)/E19 -> -0.0085321184 | F25: =-SUM(F21:F23)/F19 -> 0.11349219 | G25: =-SUM(G21:G23)/G19 -> 0.11903526 | H25: =-SUM(H21:H23)/H19 -> 0.12474463 | I25: =-SUM(I21:I23)/I19 -> 0.13062528 | J25: =-SUM(J21:J23)/J19 -> 0.13668235
B26: ROE | F26: =-SUM(F21:F23)/F19 -> 0.11349219 | G26: =-SUM(G21:G23)/G19 -> 0.11903526 | H26: =-SUM(H21:H23)/H19 -> 0.12474463 | I26: =I25 -> 0.13062528 | J26: =(J24+J19)/-J19 -> 1.0498974
B27: Avg. COC | D27: =AVERAGE(D25:K25) -> 0.1026746
B28: ROE Per Annum | D28: =AVERAGE(D26:K26) -> 0.30755894
B29: IRR | D29: =IRR(D24:I24) -> -0.17722398
B30: Accumulated ROE | D30: =SUM(D26:K26) -> 1.5377947
B31: IRR | D31: =IRR(D24:J24) -> 0.18764316
B33: The Service Success Fee (15%)
B34: Equity | D34: =I19 -> -8281149.3
B35: Return of Equity & Profit From Sale | D35: =('Investor Returns'!J15-'Investor Returns'!J10)*TS_Share -> 17178173
B36: Profit | D36: =SUM(D34:D35) -> 8897023.3
B37: TS Success Fee | D37: =-D36*suc_fee -> -1334553.5
B38: Sales proceeds | D38: =SUM(D35,D37) -> 15843619

Sheet Fin Calc
B2: Financial Measurements | C2: Schonbrunn | D2: LTC
B4: Total Cost | C4: ='Project Budget and Assumptions'!C24 -> 17508400
B5: Total Capitalization | C5: =SUM(C4:C4) -> 17508400
B6: $ Amount of Debt | C6: =0.5*C4 -> 8754200
B7: $ Amount of Equity | C7: =C5-C6 -> 8754200 | D7: =C7/C4 -> 0.5
B8: Number of Existing Units | C8: 118
B9: New Units | C9: 8
B10: Total Number of Units | C10: =C8+C9 -> 126
B11: Gross Project Square Meters | C11: 6400
B12: Price Per Door - Purchars | C12: =14000000/C8 -> 118644.07
B13: Price Per Door - renovated | C13: =C4/C10 -> 138955.56
B14: Average Income Per Door Per Month | C14: ='Op Budget (Yr1)'!O26/('Op Budget (Yr1)'!O16+'Op Budget (Yr1)'!O17+'Op Budget (Yr1)'!O18+'Op Budget (Yr1)'!O19+'Op Budget (Yr1)'!O20+'Op Budget (Yr1)'!O21+'Op Budget (Yr1)'!O22)*25 -> 1773.4981
B15: Stabilized Net Operating Income (Op Yr 5) | C15: ='Annual Projections (Full)'!H40 -> 1722142.4
B16: Stabilized Value (Op Yr 5 @ 5.5%) | C16: =C15/'Project Budget and Assumptions'!F12 -> 31311680
B17: Return on Equity (Op Yr 5) | C17: =('Annual Projections (Full)'!H40-'Annual Projections (Full)'!H42-'Annual Projections (Full)'!H44)/'Fin Calc'!C7 -> 0.16399167
B18: Cash On Cash (Op Yr 5) | C18: =('Annual Projections (Full)'!H45/'Fin Calc'!C7) -> 0.13736751

Sheet Unit Mix
A1: Unit Mix
A2: Unit Type | B2: No. of Units | C2: No. of Beds | D2: SQM / Unit | E2: Total Net SQM
A3: Studio Classic | B3: 40 | C3: 40 | D3: 20 | E3: =B3*D3 -> 800
A4: Premium | B4: 43 | C4: 43 | D4: 23 | E4: =B4*D4 -> 989
A5: Premium with terrace | B5: 18 | C5: 18 | D5: 23 | E5: =B5*D5 -> 414
A6: Suite | B6: 3 | C6: 6 | D6: 30 | E6: =B6*D6 -> 90
A7: Premium Suite | B7: 2 | C7: 4 | D7: 35 | E7: =B7*D7 -> 70
A8: Appartment | B8: 20 | C8: 80 | D8: 40 | E8: =B8*D8 -> 800
A9: Parking | B9: 30
A10: Total / Average | B10: =SUM(B3:B8) -> 126 | C10: =SUM(C3:C9) -> 191 | D10: =E10/B10 -> 25.103175 | E10: =SUM(E3:E9) -> 3163

Sheet Op Budget (Yr1)
C1: Jan | D1: Feb | E1: Mar | F1: Apr | G1: May | H1: Jun | I1: Jul | J1: Aug | K1: Sep | L1: Oct | M1: Nov | N1: Dec | O1: Annual - Y1
B2: Assumptions
B3: Number of Days | C3: 31 | D3: 28 | E3: 31 | F3: 30 | G3: 31 | H3: 30 | I3: 31 | J3: 30 | K3: 31 | L3: 30 | M3: 31 | N3: 31 | O3: =SUM(C3:N3) -> 365
B4: Avg. Occupancy | C4: 0.63 | D4: 0.68 | E4: 0.73 | F4: 0.73 | G4: 0.75 | H4: 0.78 | I4: 0.76 | J4: 0.83 | K4: 0.81 | L4: 0.8 | M4: 0.78 | N4: 0.73 | O4: =SUM(C4:N4)/12 -> 0.75083333
B6: Pricing (Net of Marketing Fees)
B7: Studio Classic | C7: 50 | D7: 55 | E7: 65 | F7: 80 | G7: 80 | H7: 85 | I7: 85 | J7: 85 | K7: 80 | L7: 70 | M7: 60 | N7: 70 | O7: =SUM(C7:N7) -> 865
B8: Premium | C8: 55 | D8: 60 | E8: 70 | F8: 85 | G8: 90 | H8: 90 | I8: 90 | J8: 95 | K8: 85 | L8: 75 | M8: 65 | N8: 75 | O8: =SUM(C8:N8) -> 935
B9: Premium with terrace | C9: 65 | D9: 70 | E9: 80 | F9: 90 | G9: 100 | H9: 105 | I9: 100 | J9: 105 | K9: 90 | L9: 85 | M9: 80 | N9: 85 | O9: =SUM(C9:N9) -> 1055
B10: Suite | C10: 85 | D10: 90 | E10: 100 | F10: 115 | G10: 120 | H10: 125 | I10: 120 | J10: 125 | K10: 115 | L10: 105 | M10: 95 | N10: 110 | O10: =SUM(C10:N10) -> 1305
B11: Premium Suite | C11: 100 | D11: 110 | E11: 115 | F11: 130 | G11: 130 | H11: 135 | I11: 130 | J11: 130 | K11: 125 | L11: 115 | M11: 110 | N11: 120 | O11: =SUM(C11:N11) -> 1450
B12: Appartment | C12: 110 | D12: 115 | E12: 120 | F12: 140 | G12: 140 | H12: 145 | I12: 140 | J12: 140 | K12: 135 | L12: 125 | M12: 120 | N12: 130 | O12: =SUM(C12:N12) -> 1560
B13: Parking | C13: 20 | D13: 20 | E13: 20 | F13: 20 | G13: 20 | H13: 20 | I13: 20 | J13: 20 | K13: 20 | L13: 20 | M13: 20 | N13: 20
B15: Occupied Days per Month
B16: Studio Classic | C16: ='Unit Mix'!$B$3*'Op Budget (Yr1)'!C3*'Op Budget (Yr1)'!C4 -> 781.2 | D16: ='Unit Mix'!$B$3*'Op Budget (Yr1)'!D3*'Op Budget (Yr1)'!D4 -> 761.6 | E16: ='Unit Mix'!$B$3*'Op Budget (Yr1)'!E3*'Op Budget (Yr1)'!E4 -> 905.2 | F16: ='Unit Mix'!$B$3*'Op Budget (Yr1)'!F3*'Op Budget (Yr1)'!F4 -> 876 | G16: ='Unit Mix'!$B$3*'Op Budget (Yr1)'!G3*'Op Budget (Yr1)'!G4 -> 930 | H16: ='Unit Mix'!$B$3*'Op Budget (Yr1)'!H3*'Op Budget (Yr1)'!H4 -> 936 | I16: ='Unit Mix'!$B$3*'Op Budget (Yr1)'!I3*'Op Budget (Yr1)'!I4 -> 942.4 | J16: ='Unit Mix'!$B$3*'Op Budget (Yr1)'!J3*'Op Budget (Yr1)'!J4 -> 996 | ... N16: ='Unit Mix'!$B$3*'Op Budget (Yr1)'!N3*'Op Budget (Yr1)'!N4 -> 905.2 | O16: =SUM(C16:N16) -> 10965.2
B17: Premium | C17: ='Unit Mix'!$B$4*'Op Budget (Yr1)'!C3*'Op Budget (Yr1)'!C4 -> 839.79 | D17: ='Unit Mix'!$B$4*'Op Budget (Yr1)'!D3*'Op Budget (Yr1)'!D4 -> 818.72 | E17: ='Unit Mix'!$B$4*'Op Budget (Yr1)'!E3*'Op Budget (Yr1)'!E4 -> 973.09 | F17: ='Unit Mix'!$B$4*'Op Budget (Yr1)'!F3*'Op Budget (Yr1)'!F4 -> 941.7 | G17: ='Unit Mix'!$B$4*'Op Budget (Yr1)'!G3*'Op Budget (Yr1)'!G4 -> 999.75 | H17: ='Unit Mix'!$B$4*'Op Budget (Yr1)'!H3*'Op Budget (Yr1)'!H4 -> 1006.2 | I17: ='Unit Mix'!$B$4*'Op Budget (Yr1)'!I3*'Op Budget (Yr1)'!I4 -> 1013.08 | J17: ='Unit Mix'!$B$4*'Op Budget (Yr1)'!J3*'Op Budget (Yr1)'!J4 -> 1070.7 | ... N17: ='Unit Mix'!$B$4*'Op Budget (Yr1)'!N3*'Op Budget (Yr1)'!N4 -> 973.09 | O17: =SUM(C17:N17) -> 11787.59
B18: Premium with terrace | C18: ='Unit Mix'!$B$5*'Op Budget (Yr1)'!C3*'Op Budget (Yr1)'!C4 -> 351.54 | D18: ='Unit Mix'!$B$5*'Op Budget (Yr1)'!D3*'Op Budget (Yr1)'!D4 -> 342.72 | E18: ='Unit Mix'!$B$5*'Op Budget (Yr1)'!E3*'Op Budget (Yr1)'!E4 -> 407.34 | F18: ='Unit Mix'!$B$5*'Op Budget (Yr1)'!F3*'Op Budget (Yr1)'!F4 -> 394.2 | G18: ='Unit Mix'!$B$5*'Op Budget (Yr1)'!G3*'Op Budget (Yr1)'!G4 -> 418.5 | H18: ='Unit Mix'!$B$5*'Op Budget (Yr1)'!H3*'Op Budget (Yr1)'!H4 -> 421.2 | I18: ='Unit Mix'!$B$5*'Op Budget (Yr1)'!I3*'Op Budget (Yr1)'!I4 -> 424.08 | J18: ='Unit Mix'!$B$5*'Op Budget (Yr1)'!J3*'Op Budget (Yr1)'!J4 -> 448.2 | ... N18: ='Unit Mix'!$B$5*'Op Budget (Yr1)'!N3*'Op Budget (Yr1)'!N4 -> 407.34 | O18: =SUM(C18:N18) -> 4934.34
B19: Suite | C19: ='Unit Mix'!$B$6*'Op Budget (Yr1)'!C3*'Op Budget (Yr1)'!C4 -> 58.59 | D19: ='Unit Mix'!$B$6*'Op Budget (Yr1)'!D3*'Op Budget (Yr1)'!D4 -> 57.12 | E19: ='Unit Mix'!$B$6*'Op Budget (Yr1)'!E3*'Op Budget (Yr1)'!E4 -> 67.89 | F19: ='Unit Mix'!$B$6*'Op Budget (Yr1)'!F3*'Op Budget (Yr1)'!F4 -> 65.7 | G19: ='Unit Mix'!$B$6*'Op Budget (Yr1)'!G3*'Op Budget (Yr1)'!G4 -> 69.75 | H19: ='Unit Mix'!$B$6*'Op Budget (Yr1)'!H3*'Op Budget (Yr1)'!H4 -> 70.2 | I19: ='Unit Mix'!$B$6*'Op Budget (Yr1)'!I3*'Op Budget (Yr1)'!I4 -> 70.68 | J19: ='Unit Mix'!$B$6*'Op Budget (Yr1)'!J3*'Op Budget (Yr1)'!J4 -> 74.7 | ... N19: ='Unit Mix'!$B$6*'Op Budget (Yr1)'!N3*'Op Budget (Yr1)'!N4 -> 67.89 | O19: =SUM(C19:N19) -> 822.39
B20: Premium Suite | C20: ='Unit Mix'!$B$7*'Op Budget (Yr1)'!C3*'Op Budget (Yr1)'!C4 -> 39.06 | D20: ='Unit Mix'!$B$7*'Op Budget (Yr1)'!D3*'Op Budget (Yr1)'!D4 -> 38.08 | E20: ='Unit Mix'!$B$7*'Op Budget (Yr1)'!E3*'Op Budget (Yr1)'!E4 -> 45.26 | F20: ='Unit Mix'!$B$7*'Op Budget (Yr1)'!F3*'Op Budget (Yr1)'!F4 -> 43.8 | G20: ='Unit Mix'!$B$7*'Op Budget (Yr1)'!G3*'Op Budget (Yr1)'!G4 -> 46.5 | H20: ='Unit Mix'!$B$7*'Op Budget (Yr1)'!H3*'Op Budget (Yr1)'!H4 -> 46.8 | I20: ='Unit Mix'!$B$7*'Op Budget (Yr1)'!I3*'Op Budget (Yr1)'!I4 -> 47.12 | J20: ='Unit Mix'!$B$7*'Op Budget (Yr1)'!J3*'Op Budget (Yr1)'!J4 -> 49.8 | ... N20: ='Unit Mix'!$B$7*'Op Budget (Yr1)'!N3*'Op Budget (Yr1)'!N4 -> 45.26 | O20: =SUM(C20:N20) -> 548.26
B21: Appartment | C21: ='Unit Mix'!$B$8*'Op Budget (Yr1)'!C3*'Op Budget (Yr1)'!C4 -> 390.6 | D21: ='Unit Mix'!$B$8*'Op Budget (Yr1)'!D3*'Op Budget (Yr1)'!D4 -> 380.8 | E21: ='Unit Mix'!$B$8*'Op Budget (Yr1)'!E3*'Op Budget (Yr1)'!E4 -> 452.6 | F21: ='Unit Mix'!$B$8*'Op Budget (Yr1)'!F3*'Op Budget (Yr1)'!F4 -> 438 | G21: ='Unit Mix'!$B$8*'Op Budget (Yr1)'!G3*'Op Budget (Yr1)'!G4 -> 465 | H21: ='Unit Mix'!$B$8*'Op Budget (Yr1)'!H3*'Op Budget (Yr1)'!H4 -> 468 | I21: ='Unit Mix'!$B$8*'Op Budget (Yr1)'!I3*'Op Budget (Yr1)'!I4 -> 471.2 | J21: ='Unit Mix'!$B$8*'Op Budget (Yr1)'!J3*'Op Budget (Yr1)'!J4 -> 498 | ... N21: ='Unit Mix'!$B$8*'Op Budget (Yr1)'!N3*'Op Budget (Yr1)'!N4 -> 452.6 | O21: =SUM(C21:N21) -> 5482.6
B22: Parking | C22: ='Unit Mix'!$B$9*'Op Budget (Yr1)'!C3*'Op Budget (Yr1)'!C4 -> 585.9 | D22: ='Unit Mix'!$B$9*'Op Budget (Yr1)'!D3*'Op Budget (Yr1)'!D4 -> 571.2 | E22: ='Unit Mix'!$B$9*'Op Budget (Yr1)'!E3*'Op Budget (Yr1)'!E4 -> 678.9 | F22: ='Unit Mix'!$B$9*'Op Budget (Yr1)'!F3*'Op Budget (Yr1)'!F4 -> 657 | G22: ='Unit Mix'!$B$9*'Op Budget (Yr1)'!G3*'Op Budget (Yr1)'!G4 -> 697.5 | H22: ='Unit Mix'!$B$9*'Op Budget (Yr1)'!H3*'Op Budget (Yr1)'!H4 -> 702 | I22: ='Unit Mix'!$B$9*'Op Budget (Yr1)'!I3*'Op Budget (Yr1)'!I4 -> 706.8 | J22: ='Unit Mix'!$B$9*'Op Budget (Yr1)'!J3*'Op Budget (Yr1)'!J4 -> 747 | ... N22: ='Unit Mix'!$B$9*'Op Budget (Yr1)'!N3*'Op Budget (Yr1)'!N4 -> 678.9 | O22: =SUM(C22:N22) -> 8223.9
B23: Total Occupied Days w/o Parking | C23: =SUM(C16:C21) -> 2460.78 | D23: =SUM(D16:D21) -> 2399.04 | E23: =SUM(E16:E21) -> 2851.38 | F23: =SUM(F16:F21) -> 2759.4 | G23: =SUM(G16:G21) -> 2929.5 | H23: =SUM(H16:H21) -> 2948.4 | I23: =SUM(I16:I21) -> 2968.56 | J23: =SUM(J16:J21) -> 3137.4 | ... O23: =SUM(O16:O21) -> 34540.38
B25: Revenues
B26: Rooms | C26: =C7*C16+C8*C17+C9*C18+C10*C19+C11*C20+C12*C21 -> 159950.7 | D26: =D7*D16+D8*D17+D9*D18+D10*D19+D11*D20+D12*D21 -> 168123.2 | E26: =E7*E16+E8*E17+E9*E18+E10*E19+E11*E20+E12*E21 -> 225847.4 | F26: =F7*F16+F8*F17+F9*F18+F10*F19+F11*F20+F12*F21 -> 260172 | G26: =G7*G16+G8*G17+G9*G18+G10*G19+G11*G20+G12*G21 -> 285742.5 | H26: =H7*H16+H8*H17+H9*H18+H10*H19+H11*H20+H12*H21 -> 297297 | I26: =I7*I16+I8*I17+I9*I18+I10*I19+I11*I20+I12*I21 -> 294264.4 | J26: =J7*J16+J8*J17+J9*J18+J10*J19+J11*J20+J12*J21 -> 318969 | ... N26: =N7*N16+N8*N17+N9*N18+N10*N19+N11*N20+N12*N21 -> 242706.75 | O26: =SUM(C26:N26) -> 3033694.9
B27: Parking | C27: =C13*C22 -> 11718 | D27: =D13*D22 -> 11424 | E27: =E13*E22 -> 13578 | F27: =F13*F22 -> 13140 | G27: =G13*G22 -> 13950 | H27: =H13*H22 -> 14040 | I27: =I13*I22 -> 14136 | J27: =J13*J22 -> 14940 | ... N27: =N13*N22 -> 13578 | O27: =SUM(C27:N27) -> 164478
B28: Ancilary | C28: =C26*4% -> 6398.028 | D28: =D26*4% -> 6724.928 | E28: =E26*4% -> 9033.896 | F28: =F26*4% -> 10406.88 | G28: =G26*4% -> 11429.7 | H28: =H26*4% -> 11891.88 | I28: =I26*4% -> 11770.576 | J28: =J26*4% -> 12758.76 | ... N28: =N26*4% -> 9708.27 | O28: =SUM(C28:N28) -> 121347.79
B29: Conference | C29: 5000 | D29: 5000 | E29: 5000 | F29: 5000 | G29: 5000 | H29: 5000 | I29: 5000 | J29: 5000 | K29: 5000 | L29: 5000 | M29: 5000 | N29: 5000 | O29: =SUM(C29:N29) -> 60000
B30: Total Revenues | C30: =SUM(C26:C29) -> 183066.73 | D30: =SUM(D26:D29) -> 191272.13 | E30: =SUM(E26:E29) -> 253459.3 | F30: =SUM(F26:F29) -> 288718.88 | G30: =SUM(G26:G29) -> 316122.2 | H30: =SUM(H26:H29) -> 328228.88 | I30: =SUM(I26:I29) -> 325170.98 | J30: =SUM(J26:J29) -> 351667.76 | ... O30: =SUM(O26:O29) -> 3379520.6
B32: Expenses
B33: Administrative Expenses
B34: Real Estate Taxes | C34: 6000 | D34: 6000 | E34: 6000 | F34: 6000 | G34: 6000 | H34: 6000 | I34: 6000 | J34: 6000 | K34: 6000 | L34: 6000 | M34: 6000 | N34: 6000 | O34: =SUM(C34:N34) -> 72000
B35: Property Insurance | C35: 1600 | D35: 1600 | E35: 1600 | F35: 1600 | G35: 1600 | H35: 1600 | I35: 1600 | J35: 1600 | K35: 1600 | L35: 1600 | M35: 1600 | N35: 1600 | O35: =SUM(C35:N35) -> 19200
B36: Marketing Services | C36: 5000 | D36: 5000 | E36: 5000 | F36: 5000 | G36: 5000 | H36: 5000 | I36: 5000 | J36: 5000 | K36: 5000 | L36: 5000 | M36: 5000 | N36: 5000 | O36: =SUM(C36:N36) -> 60000
B37: Total Administrative | C37: =SUM(C34:C36) -> 12600 | D37: =SUM(D34:D36) -> 12600 | E37: =SUM(E34:E36) -> 12600 | F37: =SUM(F34:F36) -> 12600 | G37: =SUM(G34:G36) -> 12600 | H37: =SUM(H34:H36) -> 12600 | I37: =SUM(I34:I36) -> 12600 | J37: =SUM(J34:J36) -> 12600 | ... O37: =SUM(O34:O36) -> 151200
B38: Payroll & Benefits
B39: Salaries Houskeeping+ Maitenance | C39: 23000 | D39: 23000 | E39: 23000 | F39: 23000 | G39: 23000 | H39: 23000 | I39: 23000 | J39: 23000 | K39: 23000 | L39: 23000 | M39: 23000 | N39: 23000 | O39: =SUM(C39:N39) -> 276000
B40: Salaries Reception | C40: 8000 | D40: 8000 | E40: 8000 | F40: 8000 | G40: 8000 | H40: 8000 | I40: 8000 | J40: 8000 | K40: 8000 | L40: 8000 | M40: 8000 | N40: 8000 | O40: =SUM(C40:N40) -> 96000
B41: Salaries GM | C41: 5000 | D41: 5000 | E41: 5000 | F41: 5000 | G41: 5000 | H41: 5000 | I41: 5000 | J41: 5000 | K41: 5000 | L41: 5000 | M41: 5000 | N41: 5000 | O41: =SUM(C41:N41) -> 60000
B42: Total Payroll & Benefits | C42: =SUM(C39:C41) -> 36000 | D42: =SUM(D39:D41) -> 36000 | E42: =SUM(E39:E41) -> 36000 | F42: =SUM(F39:F41) -> 36000 | G42: =SUM(G39:G41) -> 36000 | H42: =SUM(H39:H41) -> 36000 | I42: =SUM(I39:I41) -> 36000 | J42: =SUM(J39:J41) -> 36000 | ... O42: =SUM(O39:O41) -> 432000
B43: Utilities
B44: Utilities and Internet | C44: ='Project Budget and Assumptions'!$F$15*'Op Budget (Yr1)'!C30 -> 11899.337 | D44: ='Project Budget and Assumptions'!$F$15*'Op Budget (Yr1)'!D30 -> 12432.688 | E44: ='Project Budget and Assumptions'!$F$15*'Op Budget (Yr1)'!E30 -> 16474.854 | F44: ='Project Budget and Assumptions'!$F$15*'Op Budget (Yr1)'!F30 -> 18766.727 | G44: ='Project Budget and Assumptions'!$F$15*'Op Budget (Yr1)'!G30 -> 20547.943 | H44: ='Project Budget and Assumptions'!$F$15*'Op Budget (Yr1)'!H30 -> 21334.877 | I44: ='Project Budget and Assumptions'!$F$15*'Op Budget (Yr1)'!I30 -> 21136.113 | J44: ='Project Budget and Assumptions'!$F$15*'Op Budget (Yr1)'!J30 -> 22858.404 | ... N44: ='Project Budget and Assumptions'!$F$15*'Op Budget (Yr1)'!N30 -> 17614.546 | O44: =SUM(C44:N44) -> 219668.84
...

Sheet Annual Projections (Full)
D3: Op Year 1 | E3: Op Year 2 | F3: Op Year 3 | G3: Op Year 4 | H3: Op Year 5
C4: Revenues
C5: Rooms | D5: ='Op Budget (Yr1)'!O26 -> 3033694.9 | E5: =D5*1.03 -> 3124705.7 | F5: =E5*1.03 -> 3218446.9 | G5: =F5*1.03 -> 3315000.3 | H5: =G5*1.03 -> 3414450.3
C6: Parking | D6: ='Op Budget (Yr1)'!O27 -> 164478 | E6: =D6*1.03 -> 169412.34 | F6: =E6*1.03 -> 174494.71 | G6: =F6*1.03 -> 179729.55 | H6: =G6*1.03 -> 185121.44
C7: Ancilary | D7: ='Op Budget (Yr1)'!O28 -> 121347.79 | E7: =D7*1.03 -> 124988.23 | F7: =E7*1.03 -> 128737.87 | G7: =F7*1.03 -> 132600.01 | H7: =G7*1.03 -> 136578.01
C8: Conference | D8: ='Op Budget (Yr1)'!O29 -> 60000 | E8: =D8*1.03 -> 61800 | F8: =E8*1.03 -> 63654 | G8: =F8*1.03 -> 65563.62 | H8: =G8*1.03 -> 67530.529
C9: Total Revenues | D9: ='Op Budget (Yr1)'!O30 -> 3379520.6 | E9: =D9*1.03 -> 3480906.3 | F9: =E9*1.03 -> 3585333.5 | G9: =F9*1.03 -> 3692893.5 | H9: =G9*1.03 -> 3803680.3
C11: Expenses
C12: Administrative Expenses
C13: Real Estate Taxes | D13: ='Op Budget (Yr1)'!O34 -> 72000 | E13: =D13 -> 72000 | F13: =E13 -> 72000 | G13: =F13 -> 72000 | H13: =G13 -> 72000
C14: Property Insurance | D14: ='Op Budget (Yr1)'!O35 -> 19200 | E14: =D14*1.03 -> 19776 | F14: =E14*1.03 -> 20369.28 | G14: =F14*1.03 -> 20980.358 | H14: =G14*1.03 -> 21609.769
C15: Marketing Services | D15: ='Op Budget (Yr1)'!O36 -> 60000 | E15: =D15*1.03 -> 61800 | F15: =E15*1.03 -> 63654 | G15: =F15*1.03 -> 65563.62 | H15: =G15*1.03 -> 67530.529
C16: Total Administrative | D16: ='Op Budget (Yr1)'!O37 -> 151200 | E16: =D16*1.03 -> 155736 | F16: =E16*1.03 -> 160408.08 | G16: =F16*1.03 -> 165220.32 | H16: =G16*1.03 -> 170176.93
C17: Payroll & Benefits
C18: Salaries Houskeeping+ Maitenance | D18: ='Op Budget (Yr1)'!O39 -> 276000 | E18: =D18*1.02 -> 281520 | F18: =E18*1.03 -> 289965.6 | G18: =F18*1.03 -> 298664.57 | H18: =G18*1.03 -> 307624.51
C19: Salaries Reception | D19: ='Op Budget (Yr1)'!O40 -> 96000 | E19: =D19*1.02 -> 97920 | F19: =E19*1.03 -> 100857.6 | G19: =F19*1.03 -> 103883.33 | H19: =G19*1.03 -> 106999.83
C20: Salaries GM | D20: ='Op Budget (Yr1)'!O41 -> 60000 | E20: =D20*1.02 -> 61200 | F20: =E20*1.03 -> 63036 | G20: =F20*1.03 -> 64927.08 | H20: =G20*1.03 -> 66874.892
C21: Total Payroll & Benefits | D21: ='Op Budget (Yr1)'!O42 -> 432000 | E21: =D21*1.03 -> 444960 | F21: =E21*1.03 -> 458308.8 | G21: =F21*1.03 -> 472058.06 | H21: =G21*1.03 -> 486219.81
C22: Utilities
C23: Utilities and Internet | D23: ='Op Budget (Yr1)'!O44 -> 219668.84 | E23: =D23*1.02 -> 224062.22 | F23: =E23*1.02 -> 228543.46 | G23: =F23*1.02 -> 233114.33 | H23: =G23*1.02 -> 237776.62
C24: Total Utilities | D24: ='Op Budget (Yr1)'!O45 -> 219668.84 | E24: =E23 -> 224062.22 | F24: =F23 -> 228543.46 | G24: =G23 -> 233114.33 | H24: =H23 -> 237776.62
C25: Repairs & Maintenance/Services
C26: Gardening and Lift | D26: ='Op Budget (Yr1)'!O47 -> 9600 | E26: =D26*1.03 -> 9888 | F26: =E26*1.03 -> 10184.64 | G26: =F26*1.03 -> 10490.179 | H26: =G26*1.03 -> 10804.885
C27: Supplies | D27: ='Op Budget (Yr1)'!O48 -> 6000 | E27: =D27*1.03 -> 6180 | F27: =E27*1.03 -> 6365.4 | G27: =F27*1.03 -> 6556.362 | H27: =G27*1.03 -> 6753.0529
C28: Laundry/Linens | D28: ='Op Budget (Yr1)'!O49 -> 6000 | E28: =D28*1.03 -> 6180 | F28: =E28*1.03 -> 6365.4 | G28: =F28*1.03 -> 6556.362 | H28: =G28*1.03 -> 6753.0529
C29: Trash Disposal | D29: ='Op Budget (Yr1)'!O50 -> 3600 | E29: =D29*1.03 -> 3708 | F29: =E29*1.03 -> 3819.24 | G29: =F29*1.03 -> 3933.8172 | H29: =G29*1.03 -> 4051.8317
C30: Total R&M/Services | D30: ='Op Budget (Yr1)'!O51 -> 25200 | E30: =D30*1.03 -> 25956 | F30: =E30*1.03 -> 26734.68 | G30: =F30*1.03 -> 27536.72 | H30: =G30*1.03 -> 28362.822
C31: Ancilary Expences | D31: ='Op Budget (Yr1)'!O52 -> 40800 | E31: =D31*1.03 -> 42024 | F31: =E31*1.03 -> 43284.72 | G31: =F31*1.03 -> 44583.262 | H31: =G31*1.03 -> 45920.759
C32: Management | D32: ='Op Budget (Yr1)'!O53 -> 405542.48 | E32: =D32*1.03 -> 417708.75 | F32: =E32*1.03 -> 430240.01 | G32: =F32*1.03 -> 443147.21 | H32: =G32*1.03 -> 456441.63
C33: Reserves & Replacements | D33: ='Op Budget (Yr1)'!O54 -> 84488.016 | E33: =D33*1.03 -> 87022.657 | F33: =E33*1.03 -> 89633.336 | G33: =F33*1.03 -> 92322.336 | H33: =G33*1.03 -> 95092.006
C34: Misc. Expenses | D34: ='Op Budget (Yr1)'!O55 -> 50692.81 | E34: =D34*1.03 -> 52213.594 | F34: =E34*1.03 -> 53780.002 | G34: =F34*1.03 -> 55393.402 | H34: =G34*1.03 -> 57055.204
C35: Total Expenses | D35: ='Op Budget (Yr1)'!O56 -> 1405196.5 | E35: =D35*1.03 -> 1447352.4 | F35: =E35*1.03 -> 1490772.9 | G35: =F35*1.03 -> 1535496.1 | H35: =G35*1.03 -> 1581561
C37: Net Operating Income | D37: ='Op Budget (Yr1)'!O58 -> 1974324.2 | E37: =E9-E35 -> 2033553.9 | F37: =F9-F35 -> 2094560.5 | G37: =G9-G35 -> 2157397.3 | H37: =H9-H35 -> 2222119.2
C39: Gross Cash Flow | D39: =D38+D37 -> 1974324.2 | E39: =E38+E37 -> 2033553.9 | F39: =F38+F37 -> 2094560.5 | G39: =G38+G37 -> 2157397.3 | H39: =H38+H37 -> 2222119.2
C40: Owner's Share of Cash Flow | D40: =D39*(1-'Project Budget and Assumptions'!$F$18) -> 1530101.2 | E40: =E39*(1-'Project Budget and Assumptions'!$F$18) -> 1576004.3 | F40: =F39*(1-'Project Budget and Assumptions'!$F$18) -> 1623284.4 | G40: =G39*(1-'Project Budget and Assumptions'!$F$18) -> 1671982.9 | H40: =H39*(1-'Project Budget and Assumptions'!$F$18) -> 1722142.4
C42: Debt Service - Interest | D42: ='Am Table'!D21 -> 173118.74 | E42: ='Am Table'!D34 -> 168775.72 | F42: ='Am Table'!D47 -> 164345.03 | G42: ='Am Table'!D60 -> 159824.91 | H42: ='Am Table'!D73 -> 155213.55
C43: Debt Service - Principal | D43: ='Am Table'!E21 -> 215167.99 | E43: ='Am Table'!E34 -> 219511.02 | F43: ='Am Table'!E47 -> 223941.71 | G43: ='Am Table'!E60 -> 228461.83 | H43: ='Am Table'!E73 -> 233073.18
C44: Asset Management Fee (1.5% of Equity) | D44: ='Op Budget (Yr1)'!O70 -> 131313 | E44: =D44 -> 131313 | F44: =E44 -> 131313 | G44: =F44 -> 131313 | H44: =G44 -> 131313
C45: Net Cash Flow | D45: =D40-D42-D43-D44 -> 1010501.5 | E45: =E40-E42-E43-E44 -> 1056404.5 | F45: =F40-F42-F43-F44 -> 1103684.7 | G45: =G40-G42-G43-G44 -> 1152383.2 | H45: =H40-H42-H43-H44 -> 1202542.7
C46: Debt Coverage Ratio | D46: =D45/(D42+D43) -> 2.602462 | E46: =E45/(E42+E43) -> 2.7206815 | F46: =F45/(F42+F43) -> 2.8424475 | G46: =G45/(G42+G43) -> 2.9678665 | H46: =H45/(H42+H43) -> 3.0970481
...

Sheet Investor Returns
C3: Investor Returns (6 Year Hold)
C8: Investor Returns | D8: Year 0 | E8: Construction | F8: Op Year 1 | G8: Op Year 2 | H8: Op Year 3 | I8: Op Year 4 | J8: Op Year 5 | K8: IRR | L8: Equity Multiple
C9: Initial Investment | D9: =-'Fin Calc'!C7 -> -8754200
C10: Yearly Cash Flow | E10: 0 | F10: ='Annual Projections (Full)'!D45 -> 1010501.5 | G10: ='Annual Projections (Full)'!E45 -> 1056404.5 | H10: ='Annual Projections (Full)'!F45 -> 1103684.7 | I10: ='Annual Projections (Full)'!G45 -> 1152383.2 | J10: ='Annual Projections (Full)'!H45 -> 1202542.7
C11: Net Sales Proceeds | J11: ='Annual Projections (Full)'!H56 -> 23051402
C12: Subtotal | D12: =SUM(D9:D11) -> -8754200 | E12: =SUM(E9:E11) -> 0 | F12: =SUM(F9:F11) -> 1010501.5 | G12: =SUM(G9:G11) -> 1056404.5 | H12: =SUM(H9:H11) -> 1103684.7 | I12: =SUM(I9:I11) -> 1152383.2 | J12: =SUM(J9:J11) -> 24253945
C14: Less: Promote | J14: =SUM(F12+G12+H12+I12+J12+D9)*'Project Budget and Assumptions'!F20 -> 3964543.8
C15: Cash Flow | D15: =D12+D14 -> -8754200 | E15: =E12+E14 -> 0 | F15: =F12+F14 -> 1010501.5 | G15: =G12+G14 -> 1056404.5 | H15: =H12+H14 -> 1103684.7 | I15: =I12+I14 -> 1152383.2 | J15: =J12-J14 -> 20289401 | K15: =IRR(D15:J15) -> 0.20885997 | L15: =-SUM(E15:J15)/D15 -> 2.8114933
C16: Cash on Cash Return | E16: =E15/D15 -> 0 | F16: =F15/-D15 -> 0.11543048 | G16: =G15/-D15 -> 0.12067402 | H16: =H15/-D15 -> 0.12607487 | I16: =I15/-D15 -> 0.13163775 | J16: =J15/-D15 -> 2.3176762
C20: Returns
C21: Investor's Avg COC | D21: =SUM('Annual Projections (Full)'!D48:H48)/6 -> 0.10519744
C22: Investor's Avg. ROE | D22: =SUM('Annual Projections (Full)'!D49:H49)/6 -> 0.32324162
C23: Investor's IRR | D23: =K15 -> 0.20885997

Sheet Am Table
A1: AMORTIZATION | E1: Loan Term is 60 months
A3: Loan: | B3: ='Fin Calc'!C6 -> 8754200
A4: Rate: | B4: 0.02
A5: Amort: | B5: 30
A6: Payment: | B6: =PMT(B4/12,B5*12,+B3)*-1 -> 32357.228 | D6: =B6*12 -> 388286.73
B8: Beg. | C8: Pmt. | D8: Int. | E8: Princ. | F8: End
A9: 1 | B9: =+B3 -> 8754200 | C9: =+$B$6 -> 32357.228 | D9: =+B9*($B$4/12) -> 14590.333 | E9: =+C9-D9 -> 17766.895 | F9: =+B9-E9 -> 8736433.1
A10: 2 | B10: =+F9 -> 8736433.1 | C10: =+$B$6 -> 32357.228 | D10: =+B10*($B$4/12) -> 14560.722 | E10: =+C10-D10 -> 17796.506 | F10: =+B10-E10 -> 8718636.6
A11: 3 | B11: =+F10 -> 8718636.6 | C11: =+$B$6 -> 32357.228 | D11: =+B11*($B$4/12) -> 14531.061 | E11: =+C11-D11 -> 17826.167 | F11: =+B11-E11 -> 8700810.4
A12: 4 | B12: =+F11 -> 8700810.4 | C12: =+$B$6 -> 32357.228 | D12: =+B12*($B$4/12) -> 14501.351 | E12: =+C12-D12 -> 17855.877 | F12: =+B12-E12 -> 8682954.6
A13: 5 | B13: =+F12 -> 8682954.6 | C13: =+$B$6 -> 32357.228 | D13: =+B13*($B$4/12) -> 14471.591 | E13: =+C13-D13 -> 17885.637 | F13: =+B13-E13 -> 8665068.9
A14: 6 | B14: =+F13 -> 8665068.9 | C14: =+$B$6 -> 32357.228 | D14: =+B14*($B$4/12) -> 14441.782 | E14: =+C14-D14 -> 17915.446 | F14: =+B14-E14 -> 8647153.5
A15: 7 | B15: =+F14 -> 8647153.5 | C15: =+$B$6 -> 32357.228 | D15: =+B15*($B$4/12) -> 14411.922 | E15: =+C15-D15 -> 17945.305 | F15: =+B15-E15 -> 8629208.2
A16: 8 | B16: =+F15 -> 8629208.2 | C16: =+$B$6 -> 32357.228 | D16: =+B16*($B$4/12) -> 14382.014 | E16: =+C16-D16 -> 17975.214 | F16: =+B16-E16 -> 8611233
A17: 9 | B17: =+F16 -> 8611233 | C17: =+$B$6 -> 32357.228 | D17: =+B17*($B$4/12) -> 14352.055 | E17: =+C17-D17 -> 18005.173 | F17: =+B17-E17 -> 8593227.8
A18: 10 | B18: =+F17 -> 8593227.8 | C18: =+$B$6 -> 32357.228 | D18: =+B18*($B$4/12) -> 14322.046 | E18: =+C18-D18 -> 18035.182 | F18: =+B18-E18 -> 8575192.6
A19: 11 | B19: =+F18 -> 8575192.6 | C19: =+$B$6 -> 32357.228 | D19: =+B19*($B$4/12) -> 14291.988 | E19: =+C19-D19 -> 18065.24 | F19: =+B19-E19 -> 8557127.4
A20: 12 | B20: =+F19 -> 8557127.4 | C20: =+$B$6 -> 32357.228 | D20: =+B20*($B$4/12) -> 14261.879 | E20: =+C20-D20 -> 18095.349 | F20: =+B20-E20 -> 8539032
A21: Total 1 | C21: =SUM(C9:C20) -> 388286.73 | D21: =SUM(D9:D20) -> 173118.74 | E21: =SUM(E9:E20) -> 215167.99
A22: 13 | B22: =+F20 -> 8539032 | C22: =+$B$6 -> 32357.228 | D22: =+B22*($B$4/12) -> 14231.72 | E22: =+C22-D22 -> 18125.508 | F22: =+B22-E22 -> 8520906.5
A23: 14 | B23: =+F22 -> 8520906.5 | C23: =+$B$6 -> 32357.228 | D23: =+B23*($B$4/12) -> 14201.511 | E23: =+C23-D23 -> 18155.717 | F23: =+B23-E23 -> 8502750.8
A24: 15 | B24: =+F23 -> 8502750.8 | C24: =+$B$6 -> 32357.228 | D24: =+B24*($B$4/12) -> 14171.251 | E24: =+C24-D24 -> 18185.977 | F24: =+B24-E24 -> 8484564.8
A25: 16 | B25: =+F24 -> 8484564.8 | C25: =+$B$6 -> 32357.228 | D25: =+B25*($B$4/12) -> 14140.941 | E25: =+C25-D25 -> 18216.287 | F25: =+B25-E25 -> 8466348.5
A26: 17 | B26: =+F25 -> 8466348.5 | C26: =+$B$6 -> 32357.228 | D26: =+B26*($B$4/12) -> 14110.581 | E26: =+C26-D26 -> 18246.647 | F26: =+B26-E26 -> 8448101.9
A27: 18 | B27: =+F26 -> 8448101.9 | C27: =+$B$6 -> 32357.228 | D27: =+B27*($B$4/12) -> 14080.17 | E27: =+C27-D27 -> 18277.058 | F27: =+B27-E27 -> 8429824.8
A28: 19 | B28: =+F27 -> 8429824.8 | C28: =+$B$6 -> 32357.228 | D28: =+B28*($B$4/12) -> 14049.708 | E28: =+C28-D28 -> 18307.52 | F28: =+B28-E28 -> 8411517.3
A29: 20 | B29: =+F28 -> 8411517.3 | C29: =+$B$6 -> 32357.228 | D29: =+B29*($B$4/12) -> 14019.195 | E29: =+C29-D29 -> 18338.032 | F29: =+B29-E29 -> 8393179.3
A30: 21 | B30: =+F29 -> 8393179.3 | C30: =+$B$6 -> 32357.228 | D30: =+B30*($B$4/12) -> 13988.632 | E30: =+C30-D30 -> 18368.596 | F30: =+B30-E30 -> 8374810.7
A31: 22 | B31: =+F30 -> 8374810.7 | C31: =+$B$6 -> 32357.228 | D31: =+B31*($B$4/12) -> 13958.018 | E31: =+C31-D31 -> 18399.21 | F31: =+B31-E31 -> 8356411.5
A32: 23 | B32: =+F31 -> 8356411.5 | C32: =+$B$6 -> 32357.228 | D32: =+B32*($B$4/12) -> 13927.352 | E32: =+C32-D32 -> 18429.875 | F32: =+B32-E32 -> 8337981.6
A33: 24 | B33: =+F32 -> 8337981.6 | C33: =+$B$6 -> 32357.228 | D33: =+B33*($B$4/12) -> 13896.636 | E33: =+C33-D33 -> 18460.592 | F33: =+B33-E33 -> 8319521
A34: Total 2 | C34: =SUM(C22:C33) -> 388286.73 | D34: =SUM(D22:D33) -> 168775.72 | E34: =SUM(E22:E33) -> 219511.02
A35: 25 | B35: =+F33 -> 8319521 | C35: =+$B$6 -> 32357.228 | D35: =+B35*($B$4/12) -> 13865.868 | E35: =+C35-D35 -> 18491.36 | F35: =+B35-E35 -> 8301029.6
A36: 26 | B36: =+F35 -> 8301029.6 | C36: =+$B$6 -> 32357.228 | D36: =+B36*($B$4/12) -> 13835.049 | E36: =+C36-D36 -> 18522.178 | F36: =+B36-E36 -> 8282507.5
A37: 27 | B37: =+F36 -> 8282507.5 | C37: =+$B$6 -> 32357.228 | D37: =+B37*($B$4/12) -> 13804.179 | E37: =+C37-D37 -> 18553.049 | F37: =+B37-E37 -> 8263954.4
A38: 28 | B38: =+F37 -> 8263954.4 | C38: =+$B$6 -> 32357.228 | D38: =+B38*($B$4/12) -> 13773.257 | E38: =+C38-D38 -> 18583.971 | F38: =+B38-E38 -> 8245370.4
A39: 29 | B39: =+F38 -> 8245370.4 | C39: =+$B$6 -> 32357.228 | D39: =+B39*($B$4/12) -> 13742.284 | E39: =+C39-D39 -> 18614.944 | F39: =+B39-E39 -> 8226755.5
A40: 30 | B40: =+F39 -> 8226755.5 | C40: =+$B$6 -> 32357.228 | D40: =+B40*($B$4/12) -> 13711.259 | E40: =+C40-D40 -> 18645.969 | F40: =+B40-E40 -> 8208109.5
A41: 31 | B41: =+F40 -> 8208109.5 | C41: =+$B$6 -> 32357.228 | D41: =+B41*($B$4/12) -> 13680.183 | E41: =+C41-D41 -> 18677.045 | F41: =+B41-E41 -> 8189432.5
A42: 32 | B42: =+F41 -> 8189432.5 | C42: =+$B$6 -> 32357.228 | D42: =+B42*($B$4/12) -> 13649.054 | E42: =+C42-D42 -> 18708.174 | F42: =+B42-E42 -> 8170724.3
...
